<?xml version="1.0" encoding="utf-8"?>

<robot name="thorvald_ii">
  <!-- <gazebo>
    <plugin filename="libthorvald_gazebo_plugins_synch.so" name="_thorvald_gazebo_plugins">
      <alwaysOn>true</alwaysOn>
      <updateRate>20</updateRate>
      <robotNamespace></robotNamespace>
      <commandTopic>base_state</commandTopic>
      <odometryTopic>odometry/gazebo</odometryTopic>
      <odometryFrame>/base_link</odometryFrame>
      <robotBaseFrame>/base_link</robotBaseFrame>
      <steering0>/steering0</steering0>
      <steering1>/steering1</steering1>
      <steering2>/steering2</steering2>
      <steering3>/steering3</steering3>
      <steering4>/steering4</steering4>
      <steering5>/steering5</steering5>
      <steering6>/steering6</steering6>
      <steering7>/steering7</steering7>
      <steering8>/steering8</steering8>
      <steering9>/steering9</steering9>
      <steering10>/steering10</steering10>
      <wheel0>/wheel0</wheel0>
      <wheel1>/wheel1</wheel1>
      <wheel2>/wheel2</wheel2>
      <wheel3>/wheel3</wheel3>
      <wheel4>/wheel4</wheel4>
      <wheel5>/wheel5</wheel5>
      <wheel6>/wheel6</wheel6>
      <wheel7>/wheel7</wheel7>
      <wheel8>/wheel8</wheel8>
      <wheel9>/wheel9</wheel9>
      <wheel10>/wheel10</wheel10>
    </plugin>
  </gazebo> -->
  <!--
    <alwaysOn>true</alwaysOn>
    <robotNamespace>thorvald_ii</robotNamespace>
    <steering2>steering2</steering2>
    <steering1>steering1</steering1>
    <steering3>steering3</steering3>
    <steering0>steering0</steering0>
    <publishOdometryMsg>true</publishOdometryMsg>
    <publishOdometryTf>true</publishOdometryTf>
    <robotBaseFrame>base_link</robotBaseFrame>
    <commandTopic>joint_commands</commandTopic>
    <odometryTopic>odom</odometryTopic>
    <odometryFrame>odom</odometryFrame>
    <updateRate>100.0</updateRate>
    <platform_width>0.570</platform_width>
    <wheel_radius>0.400</wheel_radius>
      <torque>5.0</torque>
    </plugin>
  </gazebo> -->
  <!-- MATERIAL DEFINITIONS -->
  <material name="white">
    <color rgba="1 1 1 1"/>
  </material>
  <material name="black">
    <color rgba="0 0 0 1"/>
  </material>
  <material name="red">
    <color rgba="1 0 0 1"/>
  </material>
  <material name="green">
    <color rgba="0 1 0 1"/>
  </material>
  <material name="alu">
    <color rgba="0.75 0.75 0.75 1"/>
  </material>
  <!-- CREATE ROBOT -->
  <!-- Create base link -->
  <link name="/base_link"/>
  <link name="/top0">
    <inertial>
      <mass value="10.21"/>
      <origin rpy="0 0 0" xyz="0 0 0"/>
      <inertia ixx="0.187252250833" ixy="0.0" ixz="0.0" iyy="0.209836770833" iyz="0.0" izz="0.119499541667"/>
    </inertial>
    <visual>
      <geometry>
        <mesh filename="package://loki_description/meshes/tower_modules/DUMMY-TOWER-M.stl"/>
        <box size="0.265 0.209 0.42"/>
      </geometry>
      <material name="white"/>
    </visual>
    <collision>
      <geometry>
        <mesh filename="package://loki_description/meshes/tower_modules/DUMMY-TOWER-M.stl"/>
        <box size="0.265 0.209 0.42"/>
      </geometry>
    </collision>
  </link>
  <joint name="/base_linktop0" type="fixed">
    <parent link="/base_link"/>
    <child link="/top0"/>
    <origin rpy="0 0 4.71238898038" xyz="-0.782 -0.658 0.65"/>
    <axis xyz="0 0 1"/>
  </joint>
  <link name="/leg0">
    <inertial>
      <mass value="15.64"/>
      <origin rpy="0 0 0" xyz="0 0 0"/>
      <inertia ixx="0.035581" ixy="0.0" ixz="0.0" iyy="0.035581" iyz="0.0" izz="0.012512"/>
    </inertial>
    <visual>
      <origin rpy="0 0 4.71238898038" xyz="0 0 0"/>
      <geometry>
        <mesh filename="package://loki_description/meshes/drive_modules/836745-5-DUMMY-RevA.stl"/>
        <cylinder length="-0.15" radius="0.04"/>
        <!--mesh filename="package://thorvald_base/meshes/top_chassis.dae"/-->
      </geometry>
      <material name="white"/>
    </visual>
    <collision>
      <origin rpy="0 0 4.71238898038" xyz="0 0 0"/>
      <geometry>
        <mesh filename="package://loki_description/meshes/drive_modules/836745-5-DUMMY-RevA.stl"/>
        <cylinder length="-0.15" radius="0.04"/>
      </geometry>
    </collision>
  </link>
  <joint name="/steering0" type="continuous">
    <parent link="/base_link"/>
    <child link="/leg0"/>
    <origin rpy="0 0 1.57079632679" xyz="-0.782 -0.658 0.2"/>
    <axis xyz="0 0 1"/>
    <dynamics damping="100" friction="10000"/>
  </joint>
  <transmission name="steering0_tran">
    <type>transmission_interface/SimpleTransmission</type>
    <joint name="/steering0">
      <hardwareInterface>hardware_interface/EffortJointInterface</hardwareInterface>
    </joint>
    <actuator name="steering0_motor">
      <hardwareInterface>hardware_interface/EffortJointInterface</hardwareInterface>
      <mechanicalReduction>1</mechanicalReduction>
    </actuator>
  </transmission>
  <link name="/wheel0_link">
    <inertial>
      <mass value="6.0"/>
      <origin rpy="0 0 0" xyz="0 0 0"/>
      <inertia ixx="0.0728" ixy="0.0" ixz="0.0" iyy="0.0728" iyz="0.0" izz="0.12"/>
    </inertial>
    <visual>
      <geometry>
        <cylinder length="0.16" radius="0.2"/>
        <!-- <box size = "0.00001 0.00001 0.00001"/> -->
      </geometry>
      <material name="black"/>
    </visual>
    <collision>
      <geometry>
        <cylinder length="0.16" radius="0.2"/>
        <!-- <box size = "0.00001 0.00001 0.00001"/> -->
      </geometry>
    </collision>
  </link>
  <gazebo reference="/wheel0_link">
    <material>Gazebo/Black</material>
    <mu1 value="2"/>
    <mu2 value="2"/>
  </gazebo>
  <joint name="/wheel0" type="continuous">
    <parent link="/leg0"/>
    <child link="/wheel0_link"/>
    <origin rpy="-1.57079632679 0 0" xyz="0 0 0"/>
    <axis xyz="0 0 1"/>
    <dynamics damping="100" friction="1000"/>
  </joint>
  <transmission name="wheel0_tran">
    <type>transmission_interface/SimpleTransmission</type>
    <joint name="/wheel0">
      <hardwareInterface>hardware_interface/EffortJointInterface</hardwareInterface>
    </joint>
    <actuator name="wheel0_motor">
      <hardwareInterface>hardware_interface/EffortJointInterface</hardwareInterface>
      <mechanicalReduction>1</mechanicalReduction>
    </actuator>
  </transmission>
  <!-- -->
  <!--
    <link name="$(arg tf_prefix)/rod_l_${wheel}">
      <visual>
        <geometry>
          <cylinder length="20" radius="0.01"/>
        </geometry>
	<material name="red" />
      </visual>
    </link>
      
    
    <joint name="$(arg tf_prefix)/rod_l_${wheel}" type="fixed">
      <parent link="$(arg tf_prefix)/${wheel}_link"/>
      <child link="$(arg tf_prefix)/rod_l_${wheel}"/>
      <origin xyz="0 0 10" rpy="0 0 0"/>
      <axis xyz="0 0 1"/>
    </joint>

    <link name="$(arg tf_prefix)/rod_r_${wheel}">
      <visual>
        <geometry>
          <cylinder length="20" radius="0.01"/>
        </geometry>
	<material name="green" />
      </visual>
    </link>
    
    <joint name="$(arg tf_prefix)/rod_r_${wheel}" type="fixed">
      <parent link="$(arg tf_prefix)/${wheel}_link"/>
      <child link="$(arg tf_prefix)/rod_r_${wheel}"/>
      <origin xyz="0 0 -10" rpy="0 0 0"/>
      <axis xyz="0 0 1"/>
    </joint>



    <link name="$(arg tf_prefix)/rod2_l_${wheel}">
      <visual>
        <geometry>
          <cylinder length="80" radius="0.01"/>
        </geometry>
	<material name="red" />
      </visual>
    </link>

    <joint name="$(arg tf_prefix)/rod2_l_${wheel}" type="fixed">
      <parent link="$(arg tf_prefix)/rod_l_${wheel}"/>
      <child link="$(arg tf_prefix)/rod2_l_${wheel}"/>
      <origin xyz="0 0 40" rpy="0 0 0"/>
      <axis xyz="0 0 1"/>
    </joint>

    <link name="$(arg tf_prefix)/rod2_r_${wheel}">
      <visual>
        <geometry>
          <cylinder length="80" radius="0.01"/>
        </geometry>
	<material name="green" />
      </visual>
    </link>
    
    <joint name="$(arg tf_prefix)/rod2_r_${wheel}" type="fixed">
      <parent link="$(arg tf_prefix)/rod_r_${wheel}"/>
      <child link="$(arg tf_prefix)/rod2_r_${wheel}"/>
      <origin xyz="0 0 -40" rpy="0 0 0"/>
      <axis xyz="0 0 1"/>
    </joint>
    -->
  <!-- -->
  <link name="/top1">
    <inertial>
      <mass value="10.21"/>
      <origin rpy="0 0 0" xyz="0 0 0"/>
      <inertia ixx="0.187252250833" ixy="0.0" ixz="0.0" iyy="0.209836770833" iyz="0.0" izz="0.119499541667"/>
    </inertial>
    <visual>
      <geometry>
        <mesh filename="package://loki_description/meshes/tower_modules/DUMMY-TOWER-MIRROR-M.stl"/>
        <box size="0.265 0.209 0.42"/>
      </geometry>
      <material name="white"/>
    </visual>
    <collision>
      <geometry>
        <mesh filename="package://loki_description/meshes/tower_modules/DUMMY-TOWER-MIRROR-M.stl"/>
        <box size="0.265 0.209 0.42"/>
      </geometry>
    </collision>
  </link>
  <joint name="/base_linktop1" type="fixed">
    <parent link="/base_link"/>
    <child link="/top1"/>
    <origin rpy="0 0 1.57079632679" xyz="0.782 -0.658 0.65"/>
    <axis xyz="0 0 1"/>
  </joint>
  <link name="/leg1">
    <inertial>
      <mass value="15.64"/>
      <origin rpy="0 0 0" xyz="0 0 0"/>
      <inertia ixx="0.035581" ixy="0.0" ixz="0.0" iyy="0.035581" iyz="0.0" izz="0.012512"/>
    </inertial>
    <visual>
      <origin rpy="0 0 1.57079632679" xyz="0 0 0"/>
      <geometry>
        <mesh filename="package://loki_description/meshes/drive_modules/836745-5-DUMMY-MIRROR-RevA.stl"/>
        <cylinder length="-0.15" radius="0.04"/>
        <!--mesh filename="package://thorvald_base/meshes/top_chassis.dae"/-->
      </geometry>
      <material name="white"/>
    </visual>
    <collision>
      <origin rpy="0 0 1.57079632679" xyz="0 0 0"/>
      <geometry>
        <mesh filename="package://loki_description/meshes/drive_modules/836745-5-DUMMY-MIRROR-RevA.stl"/>
        <cylinder length="-0.15" radius="0.04"/>
      </geometry>
    </collision>
  </link>
  <joint name="/steering1" type="continuous">
    <parent link="/base_link"/>
    <child link="/leg1"/>
    <origin rpy="0 0 1.57079632679" xyz="0.782 -0.658 0.2"/>
    <axis xyz="0 0 1"/>
    <dynamics damping="100" friction="10000"/>
  </joint>
  <transmission name="steering1_tran">
    <type>transmission_interface/SimpleTransmission</type>
    <joint name="/steering1">
      <hardwareInterface>hardware_interface/EffortJointInterface</hardwareInterface>
    </joint>
    <actuator name="steering1_motor">
      <hardwareInterface>hardware_interface/EffortJointInterface</hardwareInterface>
      <mechanicalReduction>1</mechanicalReduction>
    </actuator>
  </transmission>
  <link name="/wheel1_link">
    <inertial>
      <mass value="6.0"/>
      <origin rpy="0 0 0" xyz="0 0 0"/>
      <inertia ixx="0.0728" ixy="0.0" ixz="0.0" iyy="0.0728" iyz="0.0" izz="0.12"/>
    </inertial>
    <visual>
      <geometry>
        <cylinder length="0.16" radius="0.2"/>
        <!-- <box size = "0.00001 0.00001 0.00001"/> -->
      </geometry>
      <material name="black"/>
    </visual>
    <collision>
      <geometry>
        <cylinder length="0.16" radius="0.2"/>
        <!-- <box size = "0.00001 0.00001 0.00001"/> -->
      </geometry>
    </collision>
  </link>
  <gazebo reference="/wheel1_link">
    <material>Gazebo/Black</material>
    <mu1 value="2"/>
    <mu2 value="2"/>
  </gazebo>
  <joint name="/wheel1" type="continuous">
    <parent link="/leg1"/>
    <child link="/wheel1_link"/>
    <origin rpy="-1.57079632679 0 0" xyz="0 0 0"/>
    <axis xyz="0 0 1"/>
    <dynamics damping="100" friction="1000"/>
  </joint>
  <transmission name="wheel1_tran">
    <type>transmission_interface/SimpleTransmission</type>
    <joint name="/wheel1">
      <hardwareInterface>hardware_interface/EffortJointInterface</hardwareInterface>
    </joint>
    <actuator name="wheel1_motor">
      <hardwareInterface>hardware_interface/EffortJointInterface</hardwareInterface>
      <mechanicalReduction>1</mechanicalReduction>
    </actuator>
  </transmission>
  <!-- -->
  <!--
    <link name="$(arg tf_prefix)/rod_l_${wheel}">
      <visual>
        <geometry>
          <cylinder length="20" radius="0.01"/>
        </geometry>
	<material name="red" />
      </visual>
    </link>
      
    
    <joint name="$(arg tf_prefix)/rod_l_${wheel}" type="fixed">
      <parent link="$(arg tf_prefix)/${wheel}_link"/>
      <child link="$(arg tf_prefix)/rod_l_${wheel}"/>
      <origin xyz="0 0 10" rpy="0 0 0"/>
      <axis xyz="0 0 1"/>
    </joint>

    <link name="$(arg tf_prefix)/rod_r_${wheel}">
      <visual>
        <geometry>
          <cylinder length="20" radius="0.01"/>
        </geometry>
	<material name="green" />
      </visual>
    </link>
    
    <joint name="$(arg tf_prefix)/rod_r_${wheel}" type="fixed">
      <parent link="$(arg tf_prefix)/${wheel}_link"/>
      <child link="$(arg tf_prefix)/rod_r_${wheel}"/>
      <origin xyz="0 0 -10" rpy="0 0 0"/>
      <axis xyz="0 0 1"/>
    </joint>



    <link name="$(arg tf_prefix)/rod2_l_${wheel}">
      <visual>
        <geometry>
          <cylinder length="80" radius="0.01"/>
        </geometry>
	<material name="red" />
      </visual>
    </link>

    <joint name="$(arg tf_prefix)/rod2_l_${wheel}" type="fixed">
      <parent link="$(arg tf_prefix)/rod_l_${wheel}"/>
      <child link="$(arg tf_prefix)/rod2_l_${wheel}"/>
      <origin xyz="0 0 40" rpy="0 0 0"/>
      <axis xyz="0 0 1"/>
    </joint>

    <link name="$(arg tf_prefix)/rod2_r_${wheel}">
      <visual>
        <geometry>
          <cylinder length="80" radius="0.01"/>
        </geometry>
	<material name="green" />
      </visual>
    </link>
    
    <joint name="$(arg tf_prefix)/rod2_r_${wheel}" type="fixed">
      <parent link="$(arg tf_prefix)/rod_r_${wheel}"/>
      <child link="$(arg tf_prefix)/rod2_r_${wheel}"/>
      <origin xyz="0 0 -40" rpy="0 0 0"/>
      <axis xyz="0 0 1"/>
    </joint>
    -->
  <!-- -->
  <link name="/top2">
    <inertial>
      <mass value="10.21"/>
      <origin rpy="0 0 0" xyz="0 0 0"/>
      <inertia ixx="0.187252250833" ixy="0.0" ixz="0.0" iyy="0.209836770833" iyz="0.0" izz="0.119499541667"/>
    </inertial>
    <visual>
      <geometry>
        <mesh filename="package://loki_description/meshes/tower_modules/DUMMY-TOWER-M.stl"/>
        <box size="0.265 0.209 0.42"/>
      </geometry>
      <material name="white"/>
    </visual>
    <collision>
      <geometry>
        <mesh filename="package://loki_description/meshes/tower_modules/DUMMY-TOWER-M.stl"/>
        <box size="0.265 0.209 0.42"/>
      </geometry>
    </collision>
  </link>
  <joint name="/base_linktop2" type="fixed">
    <parent link="/base_link"/>
    <child link="/top2"/>
    <origin rpy="0 0 1.57079632679" xyz="0.782 0.658 0.65"/>
    <axis xyz="0 0 1"/>
  </joint>
  <link name="/leg2">
    <inertial>
      <mass value="15.64"/>
      <origin rpy="0 0 0" xyz="0 0 0"/>
      <inertia ixx="0.035581" ixy="0.0" ixz="0.0" iyy="0.035581" iyz="0.0" izz="0.012512"/>
    </inertial>
    <visual>
      <origin rpy="0 0 1.57079632679" xyz="0 0 0"/>
      <geometry>
        <mesh filename="package://loki_description/meshes/drive_modules/836745-5-DUMMY-RevA.stl"/>
        <cylinder length="-0.15" radius="0.04"/>
        <!--mesh filename="package://thorvald_base/meshes/top_chassis.dae"/-->
      </geometry>
      <material name="white"/>
    </visual>
    <collision>
      <origin rpy="0 0 1.57079632679" xyz="0 0 0"/>
      <geometry>
        <mesh filename="package://loki_description/meshes/drive_modules/836745-5-DUMMY-RevA.stl"/>
        <cylinder length="-0.15" radius="0.04"/>
      </geometry>
    </collision>
  </link>
  <joint name="/steering2" type="continuous">
    <parent link="/base_link"/>
    <child link="/leg2"/>
    <origin rpy="0 0 1.57079632679" xyz="0.782 0.658 0.2"/>
    <axis xyz="0 0 1"/>
    <dynamics damping="100" friction="10000"/>
  </joint>
  <transmission name="steering2_tran">
    <type>transmission_interface/SimpleTransmission</type>
    <joint name="/steering2">
      <hardwareInterface>hardware_interface/EffortJointInterface</hardwareInterface>
    </joint>
    <actuator name="steering2_motor">
      <hardwareInterface>hardware_interface/EffortJointInterface</hardwareInterface>
      <mechanicalReduction>1</mechanicalReduction>
    </actuator>
  </transmission>
  <link name="/wheel2_link">
    <inertial>
      <mass value="6.0"/>
      <origin rpy="0 0 0" xyz="0 0 0"/>
      <inertia ixx="0.0728" ixy="0.0" ixz="0.0" iyy="0.0728" iyz="0.0" izz="0.12"/>
    </inertial>
    <visual>
      <geometry>
        <cylinder length="0.16" radius="0.2"/>
        <!-- <box size = "0.00001 0.00001 0.00001"/> -->
      </geometry>
      <material name="black"/>
    </visual>
    <collision>
      <geometry>
        <cylinder length="0.16" radius="0.2"/>
        <!-- <box size = "0.00001 0.00001 0.00001"/> -->
      </geometry>
    </collision>
  </link>
  <gazebo reference="/wheel2_link">
    <material>Gazebo/Black</material>
    <mu1 value="2"/>
    <mu2 value="2"/>
  </gazebo>
  <joint name="/wheel2" type="continuous">
    <parent link="/leg2"/>
    <child link="/wheel2_link"/>
    <origin rpy="-1.57079632679 0 0" xyz="0 0 0"/>
    <axis xyz="0 0 1"/>
    <dynamics damping="100" friction="1000"/>
  </joint>
  <transmission name="wheel2_tran">
    <type>transmission_interface/SimpleTransmission</type>
    <joint name="/wheel2">
      <hardwareInterface>hardware_interface/EffortJointInterface</hardwareInterface>
    </joint>
    <actuator name="wheel2_motor">
      <hardwareInterface>hardware_interface/EffortJointInterface</hardwareInterface>
      <mechanicalReduction>1</mechanicalReduction>
    </actuator>
  </transmission>
  <!-- -->
  <!--
    <link name="$(arg tf_prefix)/rod_l_${wheel}">
      <visual>
        <geometry>
          <cylinder length="20" radius="0.01"/>
        </geometry>
	<material name="red" />
      </visual>
    </link>
      
    
    <joint name="$(arg tf_prefix)/rod_l_${wheel}" type="fixed">
      <parent link="$(arg tf_prefix)/${wheel}_link"/>
      <child link="$(arg tf_prefix)/rod_l_${wheel}"/>
      <origin xyz="0 0 10" rpy="0 0 0"/>
      <axis xyz="0 0 1"/>
    </joint>

    <link name="$(arg tf_prefix)/rod_r_${wheel}">
      <visual>
        <geometry>
          <cylinder length="20" radius="0.01"/>
        </geometry>
	<material name="green" />
      </visual>
    </link>
    
    <joint name="$(arg tf_prefix)/rod_r_${wheel}" type="fixed">
      <parent link="$(arg tf_prefix)/${wheel}_link"/>
      <child link="$(arg tf_prefix)/rod_r_${wheel}"/>
      <origin xyz="0 0 -10" rpy="0 0 0"/>
      <axis xyz="0 0 1"/>
    </joint>



    <link name="$(arg tf_prefix)/rod2_l_${wheel}">
      <visual>
        <geometry>
          <cylinder length="80" radius="0.01"/>
        </geometry>
	<material name="red" />
      </visual>
    </link>

    <joint name="$(arg tf_prefix)/rod2_l_${wheel}" type="fixed">
      <parent link="$(arg tf_prefix)/rod_l_${wheel}"/>
      <child link="$(arg tf_prefix)/rod2_l_${wheel}"/>
      <origin xyz="0 0 40" rpy="0 0 0"/>
      <axis xyz="0 0 1"/>
    </joint>

    <link name="$(arg tf_prefix)/rod2_r_${wheel}">
      <visual>
        <geometry>
          <cylinder length="80" radius="0.01"/>
        </geometry>
	<material name="green" />
      </visual>
    </link>
    
    <joint name="$(arg tf_prefix)/rod2_r_${wheel}" type="fixed">
      <parent link="$(arg tf_prefix)/rod_r_${wheel}"/>
      <child link="$(arg tf_prefix)/rod2_r_${wheel}"/>
      <origin xyz="0 0 -40" rpy="0 0 0"/>
      <axis xyz="0 0 1"/>
    </joint>
    -->
  <!-- -->
  <link name="/top3">
    <inertial>
      <mass value="10.21"/>
      <origin rpy="0 0 0" xyz="0 0 0"/>
      <inertia ixx="0.187252250833" ixy="0.0" ixz="0.0" iyy="0.209836770833" iyz="0.0" izz="0.119499541667"/>
    </inertial>
    <visual>
      <geometry>
        <mesh filename="package://loki_description/meshes/tower_modules/DUMMY-TOWER-MIRROR-M.stl"/>
        <box size="0.265 0.209 0.42"/>
      </geometry>
      <material name="white"/>
    </visual>
    <collision>
      <geometry>
        <mesh filename="package://loki_description/meshes/tower_modules/DUMMY-TOWER-MIRROR-M.stl"/>
        <box size="0.265 0.209 0.42"/>
      </geometry>
    </collision>
  </link>
  <joint name="/base_linktop3" type="fixed">
    <parent link="/base_link"/>
    <child link="/top3"/>
    <origin rpy="0 0 4.71238898038" xyz="-0.782 0.658 0.65"/>
    <axis xyz="0 0 1"/>
  </joint>
  <link name="/leg3">
    <inertial>
      <mass value="15.64"/>
      <origin rpy="0 0 0" xyz="0 0 0"/>
      <inertia ixx="0.035581" ixy="0.0" ixz="0.0" iyy="0.035581" iyz="0.0" izz="0.012512"/>
    </inertial>
    <visual>
      <origin rpy="0 0 4.71238898038" xyz="0 0 0"/>
      <geometry>
        <mesh filename="package://loki_description/meshes/drive_modules/836745-5-DUMMY-MIRROR-RevA.stl"/>
        <cylinder length="-0.15" radius="0.04"/>
        <!--mesh filename="package://thorvald_base/meshes/top_chassis.dae"/-->
      </geometry>
      <material name="white"/>
    </visual>
    <collision>
      <origin rpy="0 0 4.71238898038" xyz="0 0 0"/>
      <geometry>
        <mesh filename="package://loki_description/meshes/drive_modules/836745-5-DUMMY-MIRROR-RevA.stl"/>
        <cylinder length="-0.15" radius="0.04"/>
      </geometry>
    </collision>
  </link>
  <joint name="/steering3" type="continuous">
    <parent link="/base_link"/>
    <child link="/leg3"/>
    <origin rpy="0 0 1.57079632679" xyz="-0.782 0.658 0.2"/>
    <axis xyz="0 0 1"/>
    <dynamics damping="100" friction="10000"/>
  </joint>
  <transmission name="steering3_tran">
    <type>transmission_interface/SimpleTransmission</type>
    <joint name="/steering3">
      <hardwareInterface>hardware_interface/EffortJointInterface</hardwareInterface>
    </joint>
    <actuator name="steering3_motor">
      <hardwareInterface>hardware_interface/EffortJointInterface</hardwareInterface>
      <mechanicalReduction>1</mechanicalReduction>
    </actuator>
  </transmission>
  <link name="/wheel3_link">
    <inertial>
      <mass value="6.0"/>
      <origin rpy="0 0 0" xyz="0 0 0"/>
      <inertia ixx="0.0728" ixy="0.0" ixz="0.0" iyy="0.0728" iyz="0.0" izz="0.12"/>
    </inertial>
    <visual>
      <geometry>
        <cylinder length="0.16" radius="0.2"/>
        <!-- <box size = "0.00001 0.00001 0.00001"/> -->
      </geometry>
      <material name="black"/>
    </visual>
    <collision>
      <geometry>
        <cylinder length="0.16" radius="0.2"/>
        <!-- <box size = "0.00001 0.00001 0.00001"/> -->
      </geometry>
    </collision>
  </link>
  <gazebo reference="/wheel3_link">
    <material>Gazebo/Black</material>
    <mu1 value="2"/>
    <mu2 value="2"/>
  </gazebo>
  <joint name="/wheel3" type="continuous">
    <parent link="/leg3"/>
    <child link="/wheel3_link"/>
    <origin rpy="-1.57079632679 0 0" xyz="0 0 0"/>
    <axis xyz="0 0 1"/>
    <dynamics damping="100" friction="1000"/>
  </joint>
  <transmission name="wheel3_tran">
    <type>transmission_interface/SimpleTransmission</type>
    <joint name="/wheel3">
      <hardwareInterface>hardware_interface/EffortJointInterface</hardwareInterface>
    </joint>
    <actuator name="wheel3_motor">
      <hardwareInterface>hardware_interface/EffortJointInterface</hardwareInterface>
      <mechanicalReduction>1</mechanicalReduction>
    </actuator>
  </transmission>
  <!-- -->
  <!--
    <link name="$(arg tf_prefix)/rod_l_${wheel}">
      <visual>
        <geometry>
          <cylinder length="20" radius="0.01"/>
        </geometry>
	<material name="red" />
      </visual>
    </link>
      
    
    <joint name="$(arg tf_prefix)/rod_l_${wheel}" type="fixed">
      <parent link="$(arg tf_prefix)/${wheel}_link"/>
      <child link="$(arg tf_prefix)/rod_l_${wheel}"/>
      <origin xyz="0 0 10" rpy="0 0 0"/>
      <axis xyz="0 0 1"/>
    </joint>

    <link name="$(arg tf_prefix)/rod_r_${wheel}">
      <visual>
        <geometry>
          <cylinder length="20" radius="0.01"/>
        </geometry>
	<material name="green" />
      </visual>
    </link>
    
    <joint name="$(arg tf_prefix)/rod_r_${wheel}" type="fixed">
      <parent link="$(arg tf_prefix)/${wheel}_link"/>
      <child link="$(arg tf_prefix)/rod_r_${wheel}"/>
      <origin xyz="0 0 -10" rpy="0 0 0"/>
      <axis xyz="0 0 1"/>
    </joint>



    <link name="$(arg tf_prefix)/rod2_l_${wheel}">
      <visual>
        <geometry>
          <cylinder length="80" radius="0.01"/>
        </geometry>
	<material name="red" />
      </visual>
    </link>

    <joint name="$(arg tf_prefix)/rod2_l_${wheel}" type="fixed">
      <parent link="$(arg tf_prefix)/rod_l_${wheel}"/>
      <child link="$(arg tf_prefix)/rod2_l_${wheel}"/>
      <origin xyz="0 0 40" rpy="0 0 0"/>
      <axis xyz="0 0 1"/>
    </joint>

    <link name="$(arg tf_prefix)/rod2_r_${wheel}">
      <visual>
        <geometry>
          <cylinder length="80" radius="0.01"/>
        </geometry>
	<material name="green" />
      </visual>
    </link>
    
    <joint name="$(arg tf_prefix)/rod2_r_${wheel}" type="fixed">
      <parent link="$(arg tf_prefix)/rod_r_${wheel}"/>
      <child link="$(arg tf_prefix)/rod2_r_${wheel}"/>
      <origin xyz="0 0 -40" rpy="0 0 0"/>
      <axis xyz="0 0 1"/>
    </joint>
    -->
  <!-- -->
  <link name="/corner0_1">
    <inertial>
      <mass value="0.915"/>
      <origin rpy="0 0 0" xyz="0 0 0"/>
      <inertia ixx="0.001282525" ixy="0.0" ixz="0.0" iyy="0.001751005" iyz="0.0" izz="0.002989"/>
    </inertial>
    <visual>
      <geometry>
        <mesh filename="package://loki_description/meshes/clamps/DUMMY-T-BRACKET.stl"/>
        <box size="0.140 0.116 0.058"/>
      </geometry>
      <material name="alu"/>
    </visual>
    <collision>
      <geometry>
        <box size="0.140 0.116 0.058"/>
      </geometry>
    </collision>
  </link>
  <link name="/corner0_2">
    <inertial>
      <mass value="0.915"/>
      <origin rpy="0 0 0" xyz="0 0 0"/>
      <inertia ixx="0.001282525" ixy="0.0" ixz="0.0" iyy="0.001751005" iyz="0.0" izz="0.002989"/>
    </inertial>
    <visual>
      <geometry>
        <mesh filename="package://loki_description/meshes/clamps/DUMMY-T-BRACKET.stl"/>
        <box size="0.140 0.116 0.058"/>
      </geometry>
      <material name="alu"/>
    </visual>
    <collision>
      <geometry>
        <box size="0.140 0.116 0.058"/>
      </geometry>
    </collision>
  </link>
  <link name="/corner0">
    <inertial>
      <mass value="0.915"/>
      <origin rpy="0 0 0" xyz="0 0 0"/>
      <inertia ixx="0.001807125" ixy="0.0" ixz="0.0" iyy="0.001807125" iyz="0.0" izz="0.000183"/>
    </inertial>
    <visual>
      <geometry>
        <cylinder length="0.15" radius="0.02"/>
        <!-- <box size = "0.00001 0.00001 0.00001" /> -->
      </geometry>
      <material name="alu"/>
    </visual>
    <collision>
      <geometry>
        <cylinder length="0.15" radius="0.02"/>
      </geometry>
    </collision>
  </link>
  <joint name="/corner0_link_1" type="fixed">
    <parent link="/corner0"/>
    <child link="/corner0_1"/>
    <origin rpy="0 0 0" xyz="0.057 0 -0.075"/>
    <axis xyz="0 0 1"/>
  </joint>
  <joint name="/corner0_link_2" type="fixed">
    <parent link="/corner0"/>
    <child link="/corner0_2"/>
    <origin rpy="0 0 0" xyz="0.057 0 0.075"/>
    <axis xyz="0 0 1"/>
  </joint>
  <joint name="/corner0_link" type="fixed">
    <parent link="/base_link"/>
    <child link="/corner0"/>
    <origin rpy="0 0 4.71238898038" xyz="-0.603 -0.658 0.65"/>
    <axis xyz="0 0 1"/>
  </joint>
  <link name="/corner1_1">
    <inertial>
      <mass value="0.915"/>
      <origin rpy="0 0 0" xyz="0 0 0"/>
      <inertia ixx="0.001282525" ixy="0.0" ixz="0.0" iyy="0.001751005" iyz="0.0" izz="0.002989"/>
    </inertial>
    <visual>
      <geometry>
        <mesh filename="package://loki_description/meshes/clamps/DUMMY-T-BRACKET.stl"/>
        <box size="0.140 0.116 0.058"/>
      </geometry>
      <material name="alu"/>
    </visual>
    <collision>
      <geometry>
        <box size="0.140 0.116 0.058"/>
      </geometry>
    </collision>
  </link>
  <link name="/corner1_2">
    <inertial>
      <mass value="0.915"/>
      <origin rpy="0 0 0" xyz="0 0 0"/>
      <inertia ixx="0.001282525" ixy="0.0" ixz="0.0" iyy="0.001751005" iyz="0.0" izz="0.002989"/>
    </inertial>
    <visual>
      <geometry>
        <mesh filename="package://loki_description/meshes/clamps/DUMMY-T-BRACKET.stl"/>
        <box size="0.140 0.116 0.058"/>
      </geometry>
      <material name="alu"/>
    </visual>
    <collision>
      <geometry>
        <box size="0.140 0.116 0.058"/>
      </geometry>
    </collision>
  </link>
  <link name="/corner1">
    <inertial>
      <mass value="0.915"/>
      <origin rpy="0 0 0" xyz="0 0 0"/>
      <inertia ixx="0.001807125" ixy="0.0" ixz="0.0" iyy="0.001807125" iyz="0.0" izz="0.000183"/>
    </inertial>
    <visual>
      <geometry>
        <cylinder length="0.15" radius="0.02"/>
        <!-- <box size = "0.00001 0.00001 0.00001" /> -->
      </geometry>
      <material name="alu"/>
    </visual>
    <collision>
      <geometry>
        <cylinder length="0.15" radius="0.02"/>
      </geometry>
    </collision>
  </link>
  <joint name="/corner1_link_1" type="fixed">
    <parent link="/corner1"/>
    <child link="/corner1_1"/>
    <origin rpy="0 0 0" xyz="0.057 0 -0.075"/>
    <axis xyz="0 0 1"/>
  </joint>
  <joint name="/corner1_link_2" type="fixed">
    <parent link="/corner1"/>
    <child link="/corner1_2"/>
    <origin rpy="0 0 0" xyz="0.057 0 0.075"/>
    <axis xyz="0 0 1"/>
  </joint>
  <joint name="/corner1_link" type="fixed">
    <parent link="/base_link"/>
    <child link="/corner1"/>
    <origin rpy="0 0 1.57079632679" xyz="0.603 -0.658 0.65"/>
    <axis xyz="0 0 1"/>
  </joint>
  <link name="/corner2_1">
    <inertial>
      <mass value="0.915"/>
      <origin rpy="0 0 0" xyz="0 0 0"/>
      <inertia ixx="0.001282525" ixy="0.0" ixz="0.0" iyy="0.001751005" iyz="0.0" izz="0.002989"/>
    </inertial>
    <visual>
      <geometry>
        <mesh filename="package://loki_description/meshes/clamps/DUMMY-T-BRACKET.stl"/>
        <box size="0.140 0.116 0.058"/>
      </geometry>
      <material name="alu"/>
    </visual>
    <collision>
      <geometry>
        <box size="0.140 0.116 0.058"/>
      </geometry>
    </collision>
  </link>
  <link name="/corner2_2">
    <inertial>
      <mass value="0.915"/>
      <origin rpy="0 0 0" xyz="0 0 0"/>
      <inertia ixx="0.001282525" ixy="0.0" ixz="0.0" iyy="0.001751005" iyz="0.0" izz="0.002989"/>
    </inertial>
    <visual>
      <geometry>
        <mesh filename="package://loki_description/meshes/clamps/DUMMY-T-BRACKET.stl"/>
        <box size="0.140 0.116 0.058"/>
      </geometry>
      <material name="alu"/>
    </visual>
    <collision>
      <geometry>
        <box size="0.140 0.116 0.058"/>
      </geometry>
    </collision>
  </link>
  <link name="/corner2">
    <inertial>
      <mass value="0.915"/>
      <origin rpy="0 0 0" xyz="0 0 0"/>
      <inertia ixx="0.001807125" ixy="0.0" ixz="0.0" iyy="0.001807125" iyz="0.0" izz="0.000183"/>
    </inertial>
    <visual>
      <geometry>
        <cylinder length="0.15" radius="0.02"/>
        <!-- <box size = "0.00001 0.00001 0.00001" /> -->
      </geometry>
      <material name="alu"/>
    </visual>
    <collision>
      <geometry>
        <cylinder length="0.15" radius="0.02"/>
      </geometry>
    </collision>
  </link>
  <joint name="/corner2_link_1" type="fixed">
    <parent link="/corner2"/>
    <child link="/corner2_1"/>
    <origin rpy="0 0 0" xyz="0.057 0 -0.075"/>
    <axis xyz="0 0 1"/>
  </joint>
  <joint name="/corner2_link_2" type="fixed">
    <parent link="/corner2"/>
    <child link="/corner2_2"/>
    <origin rpy="0 0 0" xyz="0.057 0 0.075"/>
    <axis xyz="0 0 1"/>
  </joint>
  <joint name="/corner2_link" type="fixed">
    <parent link="/base_link"/>
    <child link="/corner2"/>
    <origin rpy="0 0 1.57079632679" xyz="0.603 0.658 0.65"/>
    <axis xyz="0 0 1"/>
  </joint>
  <link name="/corner3_1">
    <inertial>
      <mass value="0.915"/>
      <origin rpy="0 0 0" xyz="0 0 0"/>
      <inertia ixx="0.001282525" ixy="0.0" ixz="0.0" iyy="0.001751005" iyz="0.0" izz="0.002989"/>
    </inertial>
    <visual>
      <geometry>
        <mesh filename="package://loki_description/meshes/clamps/DUMMY-T-BRACKET.stl"/>
        <box size="0.140 0.116 0.058"/>
      </geometry>
      <material name="alu"/>
    </visual>
    <collision>
      <geometry>
        <box size="0.140 0.116 0.058"/>
      </geometry>
    </collision>
  </link>
  <link name="/corner3_2">
    <inertial>
      <mass value="0.915"/>
      <origin rpy="0 0 0" xyz="0 0 0"/>
      <inertia ixx="0.001282525" ixy="0.0" ixz="0.0" iyy="0.001751005" iyz="0.0" izz="0.002989"/>
    </inertial>
    <visual>
      <geometry>
        <mesh filename="package://loki_description/meshes/clamps/DUMMY-T-BRACKET.stl"/>
        <box size="0.140 0.116 0.058"/>
      </geometry>
      <material name="alu"/>
    </visual>
    <collision>
      <geometry>
        <box size="0.140 0.116 0.058"/>
      </geometry>
    </collision>
  </link>
  <link name="/corner3">
    <inertial>
      <mass value="0.915"/>
      <origin rpy="0 0 0" xyz="0 0 0"/>
      <inertia ixx="0.001807125" ixy="0.0" ixz="0.0" iyy="0.001807125" iyz="0.0" izz="0.000183"/>
    </inertial>
    <visual>
      <geometry>
        <cylinder length="0.15" radius="0.02"/>
        <!-- <box size = "0.00001 0.00001 0.00001" /> -->
      </geometry>
      <material name="alu"/>
    </visual>
    <collision>
      <geometry>
        <cylinder length="0.15" radius="0.02"/>
      </geometry>
    </collision>
  </link>
  <joint name="/corner3_link_1" type="fixed">
    <parent link="/corner3"/>
    <child link="/corner3_1"/>
    <origin rpy="0 0 0" xyz="0.057 0 -0.075"/>
    <axis xyz="0 0 1"/>
  </joint>
  <joint name="/corner3_link_2" type="fixed">
    <parent link="/corner3"/>
    <child link="/corner3_2"/>
    <origin rpy="0 0 0" xyz="0.057 0 0.075"/>
    <axis xyz="0 0 1"/>
  </joint>
  <joint name="/corner3_link" type="fixed">
    <parent link="/base_link"/>
    <child link="/corner3"/>
    <origin rpy="0 0 4.71238898038" xyz="-0.603 0.658 0.65"/>
    <axis xyz="0 0 1"/>
  </joint>
  <link name="/pipe0_1">
    <inertial>
      <mass value="1"/>
      <origin rpy="0 0 0" xyz="0 0 0"/>
      <inertia ixx="0.1453" ixy="0.0" ixz="0.0" iyy="0.1453" iyz="0.0" izz="0.0002"/>
    </inertial>
    <visual>
      <geometry>
        <cylinder length="1.32" radius="0.02"/>
      </geometry>
      <material name="alu"/>
    </visual>
    <collision>
      <geometry>
        <cylinder length="1.32" radius="0.02"/>
      </geometry>
    </collision>
  </link>
  <link name="/pipe0_2">
    <inertial>
      <mass value="1"/>
      <origin rpy="0 0 0" xyz="0 0 0"/>
      <inertia ixx="0.1453" ixy="0.0" ixz="0.0" iyy="0.1453" iyz="0.0" izz="0.0002"/>
    </inertial>
    <visual>
      <geometry>
        <cylinder length="1.32" radius="0.02"/>
      </geometry>
      <material name="alu"/>
    </visual>
    <collision>
      <geometry>
        <cylinder length="1.32" radius="0.02"/>
      </geometry>
    </collision>
  </link>
  <joint name="/pipe0_link_1" type="fixed">
    <parent link="/base_link"/>
    <child link="/pipe0_1"/>
    <origin rpy="1.57079632679 0 0" xyz="0.0 -0.658 0.575"/>
    <axis xyz="0 0 1"/>
  </joint>
  <joint name="/pipe0_link_2" type="fixed">
    <parent link="/base_link"/>
    <child link="/pipe0_2"/>
    <origin rpy="1.57079632679 0 0" xyz="0.0 -0.658 0.725"/>
    <axis xyz="0 0 1"/>
  </joint>
  <link name="/pipe1_1">
    <inertial>
      <mass value="1"/>
      <origin rpy="0 0 0" xyz="0 0 0"/>
      <inertia ixx="0.1453" ixy="0.0" ixz="0.0" iyy="0.1453" iyz="0.0" izz="0.0002"/>
    </inertial>
    <visual>
      <geometry>
        <cylinder length="1.32" radius="0.02"/>
      </geometry>
      <material name="alu"/>
    </visual>
    <collision>
      <geometry>
        <cylinder length="1.32" radius="0.02"/>
      </geometry>
    </collision>
  </link>
  <link name="/pipe1_2">
    <inertial>
      <mass value="1"/>
      <origin rpy="0 0 0" xyz="0 0 0"/>
      <inertia ixx="0.1453" ixy="0.0" ixz="0.0" iyy="0.1453" iyz="0.0" izz="0.0002"/>
    </inertial>
    <visual>
      <geometry>
        <cylinder length="1.32" radius="0.02"/>
      </geometry>
      <material name="alu"/>
    </visual>
    <collision>
      <geometry>
        <cylinder length="1.32" radius="0.02"/>
      </geometry>
    </collision>
  </link>
  <joint name="/pipe1_link_1" type="fixed">
    <parent link="/base_link"/>
    <child link="/pipe1_1"/>
    <origin rpy="1.57079632679 0 0" xyz="0.0 0.658 0.575"/>
    <axis xyz="0 0 1"/>
  </joint>
  <joint name="/pipe1_link_2" type="fixed">
    <parent link="/base_link"/>
    <child link="/pipe1_2"/>
    <origin rpy="1.57079632679 0 0" xyz="0.0 0.658 0.725"/>
    <axis xyz="0 0 1"/>
  </joint>
  <link name="/bat0">
    <inertial>
      <mass value="12.88"/>
      <origin rpy="0 0 0" xyz="0 0 -0.25"/>
      <inertia ixx="0.342507106667" ixy="0.0" ixz="0.0" iyy="0.579579606667" iyz="0.0" izz="0.602998666667"/>
    </inertial>
    <visual>
      <origin rpy="0 0 0" xyz="0 0 0"/>
      <geometry>
        <mesh filename="package://loki_description/meshes/bat_enc_modules/836586-1-DUMMY-RevA.stl"/>
        <box size="0.530 0.245 0.509"/>
      </geometry>
      <material name="white"/>
    </visual>
    <collision>
      <geometry>
        <mesh filename="package://loki_description/meshes/bat_enc_modules/836586-1-DUMMY-RevA.stl"/>
        <box size="0.530 0.245 0.509"/>
      </geometry>
    </collision>
  </link>
  <joint name="/bat0_joint" type="fixed">
    <parent link="/base_link"/>
    <child link="/bat0"/>
    <origin rpy="0 0 4.71238898038" xyz="0.0 0.658 0.72"/>
    <axis xyz="0 0 1"/>
  </joint>
  <link name="/bat1">
    <inertial>
      <mass value="12.88"/>
      <origin rpy="0 0 0" xyz="0 0 -0.25"/>
      <inertia ixx="0.342507106667" ixy="0.0" ixz="0.0" iyy="0.579579606667" iyz="0.0" izz="0.602998666667"/>
    </inertial>
    <visual>
      <origin rpy="0 0 0" xyz="0 0 0"/>
      <geometry>
        <mesh filename="package://loki_description/meshes/bat_enc_modules/836586-1-DUMMY-RevA.stl"/>
        <box size="0.530 0.245 0.509"/>
      </geometry>
      <material name="white"/>
    </visual>
    <collision>
      <geometry>
        <mesh filename="package://loki_description/meshes/bat_enc_modules/836586-1-DUMMY-RevA.stl"/>
        <box size="0.530 0.245 0.509"/>
      </geometry>
    </collision>
  </link>
  <joint name="/bat1_joint" type="fixed">
    <parent link="/base_link"/>
    <child link="/bat1"/>
    <origin rpy="0 0 1.57079632679" xyz="0.0 -0.658 0.72"/>
    <axis xyz="0 0 1"/>
  </joint>
  <link name="uvtun_frame">
    <inertial>
      <origin rpy="0 0 0" xyz="0 0 0"/>
      <mass value="1"/>
      <inertia ixx="1.0" ixy="0.0" ixz="0.0" iyy="1.0" iyz="0.0" izz="1.0"/>
    </inertial>
    <visual>
      <geometry>
        <mesh filename="package://loki_description/meshes/uv_frame/uv_arc.STL"/>
      </geometry>
      <material name="whiter">
        <color rgba="1 1 1 1"/>
      </material>
    </visual>
  </link>
  <joint name="/base_uvtun_frame" type="fixed">
    <parent link="/base_link"/>
    <child link="uvtun_frame"/>
    <origin rpy="1.57079632679 0 3.14159265359" xyz="-0.525 -0.66 0.5"/>
  </joint>
  <!-- GPS Sensors-->
  <link name="gps_front">
    <visual>
      <material name="sept_color">
        <color rgba="1 0.8 0 1"/>
      </material>
      <geometry>
        <cylinder length="0.05" radius="0.10"/>
      </geometry>
    </visual>
  </link>
  <link name="gps_back">
    <visual>
      <material name="sept_color">
        <color rgba="1 0.8 0 1"/>
      </material>
      <geometry>
        <cylinder length="0.05" radius="0.10"/>
      </geometry>
    </visual>
  </link>
  <joint name="/gps_back" type="fixed">
    <parent link="/base_link"/>
    <child link="gps_back"/>
    <origin rpy="0 0 1.57079632679" xyz="-0.51 0 2.1"/>
  </joint>
  <joint name="/gps_front" type="fixed">
    <parent link="/base_link"/>
    <child link="gps_front"/>
    <origin rpy="0 0 1.57079632679" xyz="0.51 0 2.1"/>
  </joint>
  <gazebo>
    <plugin filename="libhector_gazebo_ros_gps.so" name="gazebo_ros_gps">
      <alwaysOn>1</alwaysOn>
      <updateRate>4.0</updateRate>
      <bodyName>gps_front</bodyName>
      <frameId>front_gps</frameId>
      <topicName>gps_front/fix</topicName>
      <velocityTopicName>gps_front/fix_velocity</velocityTopicName>
      <drift>5.0 5.0 5.0</drift>
      <gaussianNoise>0.1 0.1 0.1</gaussianNoise>
      <velocityDrift>0 0 0</velocityDrift>
      <velocityGaussianNoise>0.1 0.1 0.1</velocityGaussianNoise>
    </plugin>
  </gazebo>
  <gazebo>
    <plugin filename="libhector_gazebo_ros_gps.so" name="gazebo_ros_gps">
      <alwaysOn>1</alwaysOn>
      <updateRate>4.0</updateRate>
      <bodyName>gps_back</bodyName>
      <frameId>back_gps</frameId>
      <topicName>gps_back/fix</topicName>
      <velocityTopicName>gps_back/fix_velocity</velocityTopicName>
      <drift>5.0 5.0 5.0</drift>
      <gaussianNoise>0.1 0.1 0.1</gaussianNoise>
      <velocityDrift>0 0 0</velocityDrift>
      <velocityGaussianNoise>0.1 0.1 0.1</velocityGaussianNoise>
    </plugin>
  </gazebo>
  <!--Laser Sensors-->
  <link name="/hokuyo_front">
    <collision>
      <origin rpy="0 0 0" xyz="0 0 0"/>
      <geometry>
        <box size="0.1 0.1 0.1"/>
      </geometry>
    </collision>
    <visual>
      <origin rpy="0 0 0" xyz="0 0 0"/>
      <geometry>
        <mesh filename="package://loki_description/meshes/hokuyo/hokuyo.dae"/>
      </geometry>
    </visual>
    <inertial>
      <mass value="1e-5"/>
      <origin rpy="0 0 0" xyz="0 0 0"/>
      <inertia ixx="1e-6" ixy="0" ixz="0" iyy="1e-6" iyz="0" izz="1e-6"/>
    </inertial>
  </link>
  <link name="/hokuyo_back">
    <collision>
      <origin rpy="0 0 0" xyz="0 0 0"/>
      <geometry>
        <box size="0.1 0.1 0.1"/>
      </geometry>
    </collision>
    <visual>
      <origin rpy="0 0 0" xyz="0 0 0"/>
      <geometry>
        <mesh filename="package://loki_description/meshes/hokuyo/hokuyo.dae"/>
      </geometry>
    </visual>
    <inertial>
      <mass value="1e-5"/>
      <origin rpy="0 0 0" xyz="0 0 0"/>
      <inertia ixx="1e-6" ixy="0" ixz="0" iyy="1e-6" iyz="0" izz="1e-6"/>
    </inertial>
  </link>
  <joint name="base_sens_hokuyo_front" type="fixed">
    <parent link="/top1"/>
    <child link="/hokuyo_front"/>
    <axis xyz="0 1 0"/>
    <origin rpy="0.0 0.0 0.79" xyz="0.172 -0.152 -0.034"/>
  </joint>
  <joint name="base_sens_hokuyo_back" type="fixed">
    <parent link="/top3"/>
    <child link="/hokuyo_back"/>
    <axis xyz="0 1 0"/>
    <origin rpy="0.0 0.0 0.79" xyz="0.172 -0.152 -0.034"/>
  </joint>
  <gazebo reference="/hokuyo_front">
    <sensor name="_head_hokuyo_front_sensor" type="ray">
      <pose>0 0 0 0 0 0</pose>
      <visualize>true</visualize>
      <update_rate>40</update_rate>
      <always_on>1</always_on>
      <ray>
        <scan>
          <horizontal>
            <samples>720</samples>
            <resolution>1</resolution>
            <min_angle>-2.18</min_angle>
            <max_angle>2.36</max_angle>
          </horizontal>
        </scan>
        <range>
          <min>0.10</min>
          <max>30.0</max>
          <resolution>0.01</resolution>
        </range>
        <noise>
          <type>gaussian</type>
          <!-- Noise parameters based on published spec for Hokuyo laser
               achieving "+-30mm" accuracy at range < 10m.  A mean of 0.0m and
               stddev of 0.01m will put 99.7% of samples within 0.03m of the true
               reading. -->
          <mean>0.0</mean>
          <stddev>0.01</stddev>
        </noise>
      </ray>
      <plugin filename="libgazebo_ros_laser.so" name="_hokuyo_front_node">
        <topicName>scan_front</topicName>
        <frameName>hokuyo_front</frameName>
      </plugin>
    </sensor>
  </gazebo>
  <gazebo reference="/hokuyo_back">
    <sensor name="_head_hokuyo_back_sensor" type="ray">
      <pose>0 0 0 0 0 0</pose>
      <visualize>true</visualize>
      <update_rate>40</update_rate>
      <always_on>1</always_on>
      <ray>
        <scan>
          <horizontal>
            <samples>720</samples>
            <resolution>1</resolution>
            <min_angle>-2.18</min_angle>
            <max_angle>2.36</max_angle>
          </horizontal>
        </scan>
        <range>
          <min>0.10</min>
          <max>30.0</max>
          <resolution>0.01</resolution>
        </range>
        <noise>
          <type>gaussian</type>
          <!-- Noise parameters based on published spec for Hokuyo laser
               achieving "+-30mm" accuracy at range < 10m.  A mean of 0.0m and
               stddev of 0.01m will put 99.7% of samples within 0.03m of the true
               reading. -->
          <mean>0.0</mean>
          <stddev>0.01</stddev>
        </noise>
      </ray>
      <plugin filename="libgazebo_ros_laser.so" name="_hokuyo_back_node">
        <topicName>scan_back</topicName>
        <frameName>hokuyo_back</frameName>
      </plugin>
    </sensor>
  </gazebo>
  <gazebo>
    <plugin filename="libgazebo_ros_control.so" name="gazebo_ros_control">
      <!--<robotNamespace>/${robot_name}</robotNamespace>-->
    </plugin>
  </gazebo>

</robot>
